Caught error while executing target in child process-0:
  target = _retrieve_ops
  args = (<Device DACONO at 0x7fb047845e10>, 'config', 'output_folder')
  kwargs = {}

Traceback (most recent call last):
  File "src/pyats/async_/parallelcall.py", line 90, in pyats.async_.parallelcall.ChildLabor.run
  File "src/genie/cli/commands/learn.py", line 290, in genie.cli.commands.learn.LearnCommand._retrieve_ops
  File "src/genie/conf/base/api.py", line 52, in genie.conf.base.api.API.__getattr__.wrapper_match
  File "src/genie/conf/base/api.py", line 123, in genie.conf.base.api.API.get_api
AttributeError: Could not find the API under ios, and common
